#### 1.
```
class Main {
   public static void main(String args[]) {
      try {
         throw 10;
      }
      catch(int e) {
         System.out.println("Got the  Exception " + e);
      }
  }
}
int 不是Throwable 的子类
```

#### 2.
```
class Test extends Exception { }
  
class Main {
   public static void main(String args[]) { 
      try {
         throw new Test();
      }
      catch(Test t) {
         System.out.println("Got the Test Exception");
      }
      finally {
         System.out.println("Inside finally block ");
      }
  }
}
finally不管是否捕获异常代码块里面的会被执行
```
#### 3.
```
class Main {
   public static void main(String args[]) {
      int x = 0;
      int y = 10;
      int z = y/x;
  }
}
可以编译
```
#### 4.
```
class Base extends Exception {}
class Derived extends Base  {}
 
public class Main {
  public static void main(String args[]) {
   // some other stuff
   try {
       // Some monitored code
       throw new Derived();
    }
    catch(Base b)     { 
       System.out.println("Caught base class exception"); 
    }
    catch(Derived d)  { 
       System.out.println("Caught derived class exception"); 
    }
  }
} 
Base b 可以接受Derived对象 所以下面的catch总是无法执行 会报错
```
#### 5.
```
class Test
{
    public static void main (String[] args)
    {
        try
        {
            int a = 0;
            System.out.println ("a = " + a);
            int b = 20 / a;
            System.out.println ("b = " + b);
        }
 
        catch(ArithmeticException e)
        {
            System.out.println ("Divide by zero error");
        }
 
        finally
        {
            System.out.println ("inside the finally block");
        }
    }
}

a = 0
Divide by zero error
inside the finally block
```
#### 6.
```
class Test
{
    public static void main(String[] args)
    {
        try
        {
            int a[]= {1, 2, 3, 4};
            for (int i = 1; i <= 4; i++)
            {
                System.out.println ("a[" + i + "]=" + a[i] + "n");
            }
        }
         
        catch (Exception e)
        {
            System.out.println ("error = " + e);
        }
         
        catch (ArrayIndexOutOfBoundsException e)
        {
            System.out.println ("ArrayIndexOutOfBoundsException");
        }
    }
}

ArrayIndexOutOfBoundsException继承Exception 
不会走下面

```
#### 7.
```
class Test
{
    String str = "a";
 
    void A()
    {
        try
        {
            str +="b";
            B();
        }
        catch (Exception e)
        {
            str += "c";
        }
    }
 
    void B() throws Exception
    {
        try
        {
            str += "d";
            C();
        }
        catch(Exception e)
        {
            throw new Exception();
        }
        finally
        {
            str += "e";
        }
 
        str += "f";
 
    }
     
    void C() throws Exception
    {
        throw new Exception();
    }
 
    void display()
    {
        System.out.println(str);
    }
 
    public static void main(String[] args)
    {
        Test object = new Test();
        object.A();
        object.display();
    }
 
}
abdec
```
#### 8.
```
class Test
{   int count = 0;
 
    void A() throws Exception
    {
        try
        {
            count++;
             
            try
            {
                count++;
 
                try
                {
                    count++;
                    throw new Exception();
 
                }
                 
                catch(Exception ex)
                {
                    count++;
                    throw new Exception();
                }
            }
             
            catch(Exception ex)
            {
                count++;
            }
        }
         
        catch(Exception ex)
        {
            count++;
        }
 
    }
 
    void display()
    {
        System.out.println(count);
    }
 
    public static void main(String[] args) throws Exception
    {
        Test obj = new Test();
        obj.A();
        obj.display();
    }
}

5
```

#### 9.方法返回值是
```
public int myMethod(){

  try {

  return 1;

  }

  Catch (Exception e){

  return 2;

  }

  finally{

  return 3;

 }

}

3 finally 最后执行
```
#### 10.

```
 try {

      File file = new File("filename.txt");

      Scanner sc = new Scanner(file);

      throw new IOException();
    }

    catch (FileNotFoundException e) {

      System.out.println("FileNotFoundException called!!!");

    }

    catch (IOException e) {

      System.out.println("IOException called!!!");

    } 

```
#### 11.

```
try {

      File file = new File("filename.txt");

      Scanner sc = new Scanner(file);

      throw new IOException();
    }

    catch (IOException e) {

      System.out.println("IOException called!!!");

    } 
```
